Workbook

Sheet Logikk
C6: Logikk på hvordan regne flere tiltak: for å finne effekten av flere tiltak (feks tiltak x og y): romoppvarming: (romoppvarmingsbehov for aktuelt bygg)*(tiltak x kolonne H)*(tiltak y kolonne H) = levert strøm til romoppvarming ved tiltak x og y for å finne effekten av enda flere tiltak (feks tiltak x og y og z): romoppvarmingsbehov*(tiltak x kolonne H)*(tiltak y kolonne H)*(tiltak z kolonne H) = levert strøm til romoppvarming ved tiltak x, y og z Tappevann: Akkurat det samme som for romoppvarming, bare start med tappevannsbehov og bytt med kolonne H med I Elspesifit: Akkurat det samme som for romoppvarming, bare start med elspesifikt og bytt med kolonne H med J Til slutt kan man summere opp alle levert strøm. Altså til romoppvarming, tappevann og elspesifikt for å finn hva energibruken er etter at man har gjennomført tiltak
E24: Romoppvarming | F24: Tappevann | G24: Elspesifikt
A25: Småhus | B25: TEK69 | C25: Etterisolering yttervegg | D25: 1 | E25: =IF('Input til modellen'!L2*Logikk!$D25=0,1,'Input til modellen'!L2*Logikk!D$25) -> 0.84645233 | F25: =IF('Input til modellen'!M2*Logikk!$D25=0,1,'Input til modellen'!M2*$D25) -> 1 | G25: =IF('Input til modellen'!N2*Logikk!$D25=0,1,'Input til modellen'!N2*$D25) -> 1
A26: Småhus | B26: TEK69 | C26: Etterisolering av kjeller og loft | D26: 1 | E26: =IF('Input til modellen'!L3*Logikk!$D26=0,1,'Input til modellen'!L3*Logikk!D$25) -> 0.9368071 | F26: =IF('Input til modellen'!M3*Logikk!$D26=0,1,'Input til modellen'!M3*$D26) -> 1 | G26: =IF('Input til modellen'!N3*Logikk!$D26=0,1,'Input til modellen'!N3*$D26) -> 1
A27: Småhus | B27: TEK69 | C27: Oppgradering av vinduer gul liste | D27: 1 | E27: =IF('Input til modellen'!L4*Logikk!$D27=0,1,'Input til modellen'!L4*Logikk!D$25) -> 0.8131929 | F27: =IF('Input til modellen'!M4*Logikk!$D27=0,1,'Input til modellen'!M4*$D27) -> 1 | G27: =IF('Input til modellen'!N4*Logikk!$D27=0,1,'Input til modellen'!N4*$D27) -> 1
A28: Småhus | B28: TEK69 | C28: Oppgradering av vinduer standard | D28: 0 | E28: =IF('Input til modellen'!L5*Logikk!$D28=0,1,'Input til modellen'!L5*Logikk!D$25) -> 1 | F28: =IF('Input til modellen'!M5*Logikk!$D28=0,1,'Input til modellen'!M5*$D28) -> 1 | G28: =IF('Input til modellen'!N5*Logikk!$D28=0,1,'Input til modellen'!N5*$D28) -> 1
A29: Småhus | B29: TEK69 | C29: Temperaturstyring | D29: 0 | E29: =IF('Input til modellen'!L6*Logikk!$D29=0,1,'Input til modellen'!L6*Logikk!D$25) -> 1 | F29: =IF('Input til modellen'!M6*Logikk!$D29=0,1,'Input til modellen'!M6*$D29) -> 1 | G29: =IF('Input til modellen'!N6*Logikk!$D29=0,1,'Input til modellen'!N6*$D29) -> 1
A30: Småhus | B30: TEK69 | C30: Luft-luft varmepumpe | D30: 0 | E30: =IF('Input til modellen'!L7*Logikk!$D30=0,1,'Input til modellen'!L7*Logikk!D$25) -> 1 | F30: =IF('Input til modellen'!M7*Logikk!$D30=0,1,'Input til modellen'!M7*$D30) -> 1 | G30: =IF('Input til modellen'!N7*Logikk!$D30=0,1,'Input til modellen'!N7*$D30) -> 1
A31: Småhus | B31: TEK69 | C31: Luft-væske varmepumpe | D31: 0 | E31: =IF('Input til modellen'!L8*Logikk!$D31=0,1,'Input til modellen'!L8*Logikk!D$25) -> 1 | F31: =IF('Input til modellen'!M8*Logikk!$D31=0,1,'Input til modellen'!M8*$D31) -> 1 | G31: =IF('Input til modellen'!N8*Logikk!$D31=0,1,'Input til modellen'!N8*$D31) -> 1
A32: Småhus | B32: TEK69 | C32: Væske-væske varmepumpe | D32: 1 | E32: =IF('Input til modellen'!L9*Logikk!$D32=0,1,'Input til modellen'!L9*Logikk!D$25) -> 0.32142857 | F32: =IF('Input til modellen'!M9*Logikk!$D32=0,1,'Input til modellen'!M9*$D32) -> 0.64 | G32: =IF('Input til modellen'!N9*Logikk!$D32=0,1,'Input til modellen'!N9*$D32) -> 1
E33: =E32*E31*E30*E29*E28*E27*E26*E25*'Input til modellen'!H$2 -> 37.391016 | F33: =F32*F31*F30*F29*F28*F27*F26*F25*'Input til modellen'!I$2 -> 19.072 | G33: =G32*G31*G30*G29*G28*G27*G26*G25*'Input til modellen'!J$2 -> 30.1 | H33: =SUM(E33:G33) -> 86.563016

Sheet Input til modellen
A1: bygningskategori | B1: Teknisk forskrift | C1: Titlak | D1: Påvirker energimerket | E1: Besparelse per tiltak - Romoppvarming | F1: Besparelse per tiltak - Tappevann | G1: Besparelse per tiltak - Elspesifikt | H1: Romoppvarmingsbehov (kWh/m2/år) | I1: Tappevannsbehov (kWh/m2/år) | J1: Elspesifikt behov (kWh/m2/år) | K1: Total energibruk før tiltak | L1: Energibruk til romoppvarming etter tiltak | M1: Energibruk til tappevann etter tiltak | N1: Energibruk til elspesifikt etter tiltak
A2: Småhus | B2: TEK69 | C2: Etterisolering yttervegg | D2: 1 | E2: 27.7 | F2: 0 | G2: 0 | H2: ='Energibehov før tiltak'!$B$4 -> 180.4 | I2: ='Energibehov før tiltak'!$B$6 -> 29.8 | J2: =SUM('Energibehov før tiltak'!$B$5,'Energibehov før tiltak'!$B$7:$B$12) -> 30.1 | K2: =SUM(H2:J2) -> 240.3 | L2: =1-E2/H2 -> 0.84645233 | M2: 1 | N2: 1
A3: Småhus | B3: TEK69 | C3: Etterisolering av kjeller og loft | D3: 1 | E3: 11.4 | F3: 0 | G3: 0 | H3: ='Energibehov før tiltak'!$B$4 -> 180.4 | I3: ='Energibehov før tiltak'!$B$6 -> 29.8 | J3: =SUM('Energibehov før tiltak'!$B$5,'Energibehov før tiltak'!$B$7:$B$12) -> 30.1 | K3: =SUM(H3:J3) -> 240.3 | L3: =1-E3/H3 -> 0.9368071 | M3: 1 | N3: 1
A4: Småhus | B4: TEK69 | C4: Oppgradering av vinduer gul liste | D4: 1 | E4: 33.7 | F4: 0 | G4: 0 | H4: ='Energibehov før tiltak'!$B$4 -> 180.4 | I4: ='Energibehov før tiltak'!$B$6 -> 29.8 | J4: =SUM('Energibehov før tiltak'!$B$5,'Energibehov før tiltak'!$B$7:$B$12) -> 30.1 | K4: =SUM(H4:J4) -> 240.3 | L4: =1-E4/H4 -> 0.8131929 | M4: 1 | N4: 1
A5: Småhus | B5: TEK69 | C5: Oppgradering av vinduer standard | D5: 1 | E5: 41.7 | F5: 0 | G5: 0 | H5: ='Energibehov før tiltak'!$B$4 -> 180.4 | I5: ='Energibehov før tiltak'!$B$6 -> 29.8 | J5: =SUM('Energibehov før tiltak'!$B$5,'Energibehov før tiltak'!$B$7:$B$12) -> 30.1 | K5: =SUM(H5:J5) -> 240.3 | L5: =1-E5/H5 -> 0.76884701 | M5: 1 | N5: 1
A6: Småhus | B6: TEK69 | C6: Temperaturstyring | D6: 0 | E6: 10.824 | F6: 0 | G6: 0 | H6: ='Energibehov før tiltak'!$B$4 -> 180.4 | I6: ='Energibehov før tiltak'!$B$6 -> 29.8 | J6: =SUM('Energibehov før tiltak'!$B$5,'Energibehov før tiltak'!$B$7:$B$12) -> 30.1 | K6: =SUM(H6:J6) -> 240.3 | L6: =1-E6/H6 -> 0.94 | M6: 1 | N6: 1
A7: Småhus | B7: TEK69 | C7: Luft-luft varmepumpe | D7: 1 | E7: =(1-L7)*H7 -> 59.04 | F7: =(1-M7)*I7 -> 0 | G7: =(1-N7)*J7 -> 0 | H7: ='Energibehov før tiltak'!$B$4 -> 180.4 | I7: ='Energibehov før tiltak'!$B$6 -> 29.8 | J7: =SUM('Energibehov før tiltak'!$B$5,'Energibehov før tiltak'!$B$7:$B$12) -> 30.1 | K7: =SUM(H7:J7) -> 240.3 | L7: ='Regler varmepumper'!C24 -> 0.67272727 | M7: ='Regler varmepumper'!C25 -> 1 | N7: ='Regler varmepumper'!C26 -> 1
A8: Småhus | B8: TEK69 | C8: Luft-væske varmepumpe | D8: 1 | E8: =(1-L8)*H8 -> 86.592 | F8: =(1-M8)*I8 -> 8.94 | G8: =(1-N8)*J8 -> 0 | H8: ='Energibehov før tiltak'!$B$4 -> 180.4 | I8: ='Energibehov før tiltak'!$B$6 -> 29.8 | J8: =SUM('Energibehov før tiltak'!$B$5,'Energibehov før tiltak'!$B$7:$B$12) -> 30.1 | K8: =SUM(H8:J8) -> 240.3 | L8: ='Regler varmepumper'!C27 -> 0.52 | M8: ='Regler varmepumper'!C28 -> 0.7 | N8: ='Regler varmepumper'!C29 -> 1
A9: Småhus | B9: TEK69 | C9: Væske-væske varmepumpe | D9: 1 | E9: =(1-L9)*H9 -> 122.41429 | F9: =(1-M9)*I9 -> 10.728 | G9: =(1-N9)*J9 -> 0 | H9: ='Energibehov før tiltak'!$B$4 -> 180.4 | I9: ='Energibehov før tiltak'!$B$6 -> 29.8 | J9: =SUM('Energibehov før tiltak'!$B$5,'Energibehov før tiltak'!$B$7:$B$12) -> 30.1 | K9: =SUM(H9:J9) -> 240.3 | L9: ='Regler varmepumper'!C30 -> 0.32142857 | M9: ='Regler varmepumper'!C31 -> 0.64 | N9: ='Regler varmepumper'!C32 -> 1
A10: Boligblokk | B10: TEK69 | C10: Etterisolering yttervegg | D10: 1 | E10: 39.7 | F10: 0 | G10: 0 | H10: ='Energibehov før tiltak'!$H$4 -> 162.4 | I10: ='Energibehov før tiltak'!$H$6 -> 29.8 | J10: =SUM('Energibehov før tiltak'!$B$5,'Energibehov før tiltak'!$B$7:$B$12) -> 30.1 | K10: =SUM(H10:J10) -> 222.3 | L10: =1-E10/H10 -> 0.75554187 | M10: 1 | N10: 1
A11: Boligblokk | B11: TEK69 | C11: Etterisolering av kjeller og loft | D11: 1 | E11: 8.4 | F11: 0 | G11: 0 | H11: ='Energibehov før tiltak'!$H$4 -> 162.4 | I11: ='Energibehov før tiltak'!$H$6 -> 29.8 | J11: =SUM('Energibehov før tiltak'!$B$5,'Energibehov før tiltak'!$B$7:$B$12) -> 30.1 | K11: =SUM(H11:J11) -> 222.3 | L11: =1-E11/H11 -> 0.94827586 | M11: 1 | N11: 1
A12: Boligblokk | B12: TEK69 | C12: Oppgradering av vinduer gul liste | D12: 1 | E12: 31.3 | F12: 0 | G12: 0 | H12: ='Energibehov før tiltak'!$H$4 -> 162.4 | I12: ='Energibehov før tiltak'!$H$6 -> 29.8 | J12: =SUM('Energibehov før tiltak'!$B$5,'Energibehov før tiltak'!$B$7:$B$12) -> 30.1 | K12: =SUM(H12:J12) -> 222.3 | L12: =1-E12/H12 -> 0.80726601 | M12: 1 | N12: 1
A13: Boligblokk | B13: TEK69 | C13: Oppgradering av vinduer standard | D13: 1 | E13: 38.3 | F13: 0 | G13: 0 | H13: ='Energibehov før tiltak'!$H$4 -> 162.4 | I13: ='Energibehov før tiltak'!$H$6 -> 29.8 | J13: =SUM('Energibehov før tiltak'!$B$5,'Energibehov før tiltak'!$B$7:$B$12) -> 30.1 | K13: =SUM(H13:J13) -> 222.3 | L13: =1-E13/H13 -> 0.76416256 | M13: 1 | N13: 1
A14: Boligblokk | B14: TEK69 | C14: Temperaturstyring | D14: 0 | E14: 9.744 | F14: 0 | G14: 0 | H14: ='Energibehov før tiltak'!$H$4 -> 162.4 | I14: ='Energibehov før tiltak'!$H$6 -> 29.8 | J14: =SUM('Energibehov før tiltak'!$B$5,'Energibehov før tiltak'!$B$7:$B$12) -> 30.1 | K14: =SUM(H14:J14) -> 222.3 | L14: =1-E14/H14 -> 0.94 | M14: 1 | N14: 1
A15: Boligblokk | B15: TEK69 | C15: Luft-luft varmepumpe | D15: 1 | E15: =(1-L15)*H15 -> 53.149091 | F15: =(1-M15)*I15 -> 0 | G15: =(1-N15)*J15 -> 0 | H15: ='Energibehov før tiltak'!$H$4 -> 162.4 | I15: ='Energibehov før tiltak'!$H$6 -> 29.8 | J15: =SUM('Energibehov før tiltak'!$B$5,'Energibehov før tiltak'!$B$7:$B$12) -> 30.1 | K15: =SUM(H15:J15) -> 222.3 | L15: ='Regler varmepumper'!I24 -> 0.67272727 | M15: ='Regler varmepumper'!I25 -> 1 | N15: ='Regler varmepumper'!I26 -> 1
A16: Boligblokk | B16: TEK69 | C16: Luft-væske varmepumpe | D16: 1 | E16: =(1-L16)*H16 -> 77.952 | F16: =(1-M16)*I16 -> 8.94 | G16: =(1-N16)*J16 -> 0 | H16: ='Energibehov før tiltak'!$H$4 -> 162.4 | I16: ='Energibehov før tiltak'!$H$6 -> 29.8 | J16: =SUM('Energibehov før tiltak'!$B$5,'Energibehov før tiltak'!$B$7:$B$12) -> 30.1 | K16: =SUM(H16:J16) -> 222.3 | L16: ='Regler varmepumper'!I27 -> 0.52 | M16: ='Regler varmepumper'!I28 -> 0.7 | N16: ='Regler varmepumper'!I29 -> 1
A17: Boligblokk | B17: TEK69 | C17: Væske-væske varmepumpe | D17: 1 | E17: =(1-L17)*H17 -> 110.2 | F17: =(1-M17)*I17 -> 10.728 | G17: =(1-N17)*J17 -> 0 | H17: ='Energibehov før tiltak'!$H$4 -> 162.4 | I17: ='Energibehov før tiltak'!$H$6 -> 29.8 | J17: =SUM('Energibehov før tiltak'!$B$5,'Energibehov før tiltak'!$B$7:$B$12) -> 30.1 | K17: =SUM(H17:J17) -> 222.3 | L17: ='Regler varmepumper'!I30 -> 0.32142857 | M17: ='Regler varmepumper'!I31 -> 0.64 | N17: ='Regler varmepumper'!I32 -> 1
A18: Småhus | B18: TEK87 | C18: Etterisolering yttervegg | D18: 1 | E18: 15 | F18: 0 | G18: 0 | H18: ='Energibehov før tiltak'!$C$4 -> 141.4 | I18: ='Energibehov før tiltak'!$C$6 -> 29.8 | J18: =SUM('Energibehov før tiltak'!$C$5,'Energibehov før tiltak'!$C$7:$C$12) -> 29.9 | K18: =SUM(H18:J18) -> 201.1 | L18: =1-E18/H18 -> 0.89391796 | M18: 1 | N18: 1
A19: Småhus | B19: TEK87 | C19: Etterisolering av kjeller og loft | D19: 1 | E19: 4.7 | F19: 0 | G19: 0 | H19: ='Energibehov før tiltak'!$C$4 -> 141.4 | I19: ='Energibehov før tiltak'!$C$6 -> 29.8 | J19: =SUM('Energibehov før tiltak'!$C$5,'Energibehov før tiltak'!$C$7:$C$12) -> 29.9 | K19: =SUM(H19:J19) -> 201.1 | L19: =1-E19/H19 -> 0.96676096 | M19: 1 | N19: 1
A20: Småhus | B20: TEK87 | C20: Oppgradering av vinduer gul liste | D20: 1 | E20: 23.4 | F20: 0 | G20: 0 | H20: ='Energibehov før tiltak'!$C$4 -> 141.4 | I20: ='Energibehov før tiltak'!$C$6 -> 29.8 | J20: =SUM('Energibehov før tiltak'!$C$5,'Energibehov før tiltak'!$C$7:$C$12) -> 29.9 | K20: =SUM(H20:J20) -> 201.1 | L20: =1-E20/H20 -> 0.83451202 | M20: 1 | N20: 1
A21: Småhus | B21: TEK87 | C21: Oppgradering av vinduer standard | D21: 1 | E21: 31.4 | F21: 0 | G21: 0 | H21: ='Energibehov før tiltak'!$C$4 -> 141.4 | I21: ='Energibehov før tiltak'!$C$6 -> 29.8 | J21: =SUM('Energibehov før tiltak'!$C$5,'Energibehov før tiltak'!$C$7:$C$12) -> 29.9 | K21: =SUM(H21:J21) -> 201.1 | L21: =1-E21/H21 -> 0.77793494 | M21: 1 | N21: 1
A22: Småhus | B22: TEK87 | C22: Temperaturstyring | D22: 0 | E22: 8.484 | F22: 0 | G22: 0 | H22: ='Energibehov før tiltak'!$C$4 -> 141.4 | I22: ='Energibehov før tiltak'!$C$6 -> 29.8 | J22: =SUM('Energibehov før tiltak'!$C$5,'Energibehov før tiltak'!$C$7:$C$12) -> 29.9 | K22: =SUM(H22:J22) -> 201.1 | L22: =1-E22/H22 -> 0.94 | M22: 1 | N22: 1
A23: Småhus | B23: TEK87 | C23: Luft-luft varmepumpe | D23: 1 | E23: =(1-L23)*H23 -> 46.276364 | F23: =(1-M23)*I23 -> 0 | G23: =(1-N23)*J23 -> 0 | H23: ='Energibehov før tiltak'!$C$4 -> 141.4 | I23: ='Energibehov før tiltak'!$C$6 -> 29.8 | J23: =SUM('Energibehov før tiltak'!$C$5,'Energibehov før tiltak'!$C$7:$C$12) -> 29.9 | K23: =SUM(H23:J23) -> 201.1 | L23: ='Regler varmepumper'!D24 -> 0.67272727 | M23: ='Regler varmepumper'!D25 -> 1 | N23: ='Regler varmepumper'!D26 -> 1
A24: Småhus | B24: TEK87 | C24: Luft-væske varmepumpe | D24: 1 | E24: =(1-L24)*H24 -> 67.872 | F24: =(1-M24)*I24 -> 8.94 | G24: =(1-N24)*J24 -> 0 | H24: ='Energibehov før tiltak'!$C$4 -> 141.4 | I24: ='Energibehov før tiltak'!$C$6 -> 29.8 | J24: =SUM('Energibehov før tiltak'!$C$5,'Energibehov før tiltak'!$C$7:$C$12) -> 29.9 | K24: =SUM(H24:J24) -> 201.1 | L24: ='Regler varmepumper'!D27 -> 0.52 | M24: ='Regler varmepumper'!D28 -> 0.7 | N24: ='Regler varmepumper'!D29 -> 1
A25: Småhus | B25: TEK87 | C25: Væske-væske varmepumpe | D25: 1 | E25: =(1-L25)*H25 -> 95.95 | F25: =(1-M25)*I25 -> 10.728 | G25: =(1-N25)*J25 -> 0 | H25: ='Energibehov før tiltak'!$C$4 -> 141.4 | I25: ='Energibehov før tiltak'!$C$6 -> 29.8 | J25: =SUM('Energibehov før tiltak'!$C$5,'Energibehov før tiltak'!$C$7:$C$12) -> 29.9 | K25: =SUM(H25:J25) -> 201.1 | L25: ='Regler varmepumper'!D30 -> 0.32142857 | M25: ='Regler varmepumper'!D31 -> 0.64 | N25: ='Regler varmepumper'!D32 -> 1
A26: Boligblokk | B26: TEK87 | C26: Etterisolering yttervegg | D26: 1 | E26: 9.7 | F26: 0 | G26: 0 | H26: ='Energibehov før tiltak'!$I$4 -> 111.9 | I26: ='Energibehov før tiltak'!$I$6 -> 29.8 | J26: =SUM('Energibehov før tiltak'!$I$5,'Energibehov før tiltak'!$I$7:$I$12) -> 29.7 | K26: =SUM(H26:J26) -> 171.4 | L26: =1-E26/H26 -> 0.91331546 | M26: 1 | N26: 1
A27: Boligblokk | B27: TEK87 | C27: Etterisolering av kjeller og loft | D27: 1 | E27: 2.8 | F27: 0 | G27: 0 | H27: ='Energibehov før tiltak'!$I$4 -> 111.9 | I27: ='Energibehov før tiltak'!$I$6 -> 29.8 | J27: =SUM('Energibehov før tiltak'!$I$5,'Energibehov før tiltak'!$I$7:$I$12) -> 29.7 | K27: =SUM(H27:J27) -> 171.4 | L27: =1-E27/H27 -> 0.97497766 | M27: 1 | N27: 1
A28: Boligblokk | B28: TEK87 | C28: Oppgradering av vinduer gul liste | D28: 1 | E28: 21 | F28: 0 | G28: 0 | H28: ='Energibehov før tiltak'!$I$4 -> 111.9 | I28: ='Energibehov før tiltak'!$I$6 -> 29.8 | J28: =SUM('Energibehov før tiltak'!$I$5,'Energibehov før tiltak'!$I$7:$I$12) -> 29.7 | K28: =SUM(H28:J28) -> 171.4 | L28: =1-E28/H28 -> 0.81233244 | M28: 1 | N28: 1
A29: Boligblokk | B29: TEK87 | C29: Oppgradering av vinduer standard | D29: 1 | E29: 28.1 | F29: 0 | G29: 0 | H29: ='Energibehov før tiltak'!$I$4 -> 111.9 | I29: ='Energibehov før tiltak'!$I$6 -> 29.8 | J29: =SUM('Energibehov før tiltak'!$I$5,'Energibehov før tiltak'!$I$7:$I$12) -> 29.7 | K29: =SUM(H29:J29) -> 171.4 | L29: =1-E29/H29 -> 0.74888293 | M29: 1 | N29: 1
A30: Boligblokk | B30: TEK87 | C30: Temperaturstyring | D30: 0 | E30: 5.595 | F30: 0 | G30: 0 | H30: ='Energibehov før tiltak'!$I$4 -> 111.9 | I30: ='Energibehov før tiltak'!$I$6 -> 29.8 | J30: =SUM('Energibehov før tiltak'!$I$5,'Energibehov før tiltak'!$I$7:$I$12) -> 29.7 | K30: =SUM(H30:J30) -> 171.4 | L30: =1-E30/H30 -> 0.95 | M30: 1 | N30: 1
A31: Boligblokk | B31: TEK87 | C31: Luft-luft varmepumpe | D31: 1 | E31: =(1-L31)*H31 -> 36.621818 | F31: =(1-M31)*I31 -> 0 | G31: =(1-N31)*J31 -> 0 | H31: ='Energibehov før tiltak'!$I$4 -> 111.9 | I31: ='Energibehov før tiltak'!$I$6 -> 29.8 | J31: =SUM('Energibehov før tiltak'!$I$5,'Energibehov før tiltak'!$I$7:$I$12) -> 29.7 | K31: =SUM(H31:J31) -> 171.4 | L31: ='Regler varmepumper'!J24 -> 0.67272727 | M31: ='Regler varmepumper'!J25 -> 1 | N31: ='Regler varmepumper'!J26 -> 1
A32: Boligblokk | B32: TEK87 | C32: Luft-væske varmepumpe | D32: 1 | E32: =(1-L32)*H32 -> 53.712 | F32: =(1-M32)*I32 -> 8.94 | G32: =(1-N32)*J32 -> 0 | H32: ='Energibehov før tiltak'!$I$4 -> 111.9 | I32: ='Energibehov før tiltak'!$I$6 -> 29.8 | J32: =SUM('Energibehov før tiltak'!$I$5,'Energibehov før tiltak'!$I$7:$I$12) -> 29.7 | K32: =SUM(H32:J32) -> 171.4 | L32: ='Regler varmepumper'!J27 -> 0.52 | M32: ='Regler varmepumper'!J28 -> 0.7 | N32: ='Regler varmepumper'!J29 -> 1
A33: Boligblokk | B33: TEK87 | C33: Væske-væske varmepumpe | D33: 1 | E33: =(1-L33)*H33 -> 75.932143 | F33: =(1-M33)*I33 -> 10.728 | G33: =(1-N33)*J33 -> 0 | H33: ='Energibehov før tiltak'!$I$4 -> 111.9 | I33: ='Energibehov før tiltak'!$I$6 -> 29.8 | J33: =SUM('Energibehov før tiltak'!$I$5,'Energibehov før tiltak'!$I$7:$I$12) -> 29.7 | K33: =SUM(H33:J33) -> 171.4 | L33: ='Regler varmepumper'!J30 -> 0.32142857 | M33: ='Regler varmepumper'!J31 -> 0.64 | N33: ='Regler varmepumper'!J32 -> 1
A34: Småhus | B34: TEK97 | C34: Etterisolering yttervegg | D34: 1 | E34: 3.7 | F34: 0 | G34: 0 | H34: ='Energibehov før tiltak'!$D$4 -> 102.9 | I34: ='Energibehov før tiltak'!$D$6 -> 29.8 | J34: =SUM('Energibehov før tiltak'!$D$5,'Energibehov før tiltak'!$D$7:$D$12) -> 34.1 | K34: =SUM(H34:J34) -> 166.8 | L34: =1-E34/H34 -> 0.96404276 | M34: 1 | N34: 1
A35: Småhus | B35: TEK97 | C35: Etterisolering av kjeller og loft | D35: 1 | E35: 0.4 | F35: 0 | G35: 0 | H35: ='Energibehov før tiltak'!$D$4 -> 102.9 | I35: ='Energibehov før tiltak'!$D$6 -> 29.8 | J35: =SUM('Energibehov før tiltak'!$D$5,'Energibehov før tiltak'!$D$7:$D$12) -> 34.1 | K35: =SUM(H35:J35) -> 166.8 | L35: =1-E35/H35 -> 0.99611273 | M35: 1 | N35: 1
A36: Småhus | B36: TEK97 | C36: Oppgradering av vinduer gul liste | D36: 1 | E36: 14.2 | F36: 0 | G36: 0 | H36: ='Energibehov før tiltak'!$D$4 -> 102.9 | I36: ='Energibehov før tiltak'!$D$6 -> 29.8 | J36: =SUM('Energibehov før tiltak'!$D$5,'Energibehov før tiltak'!$D$7:$D$12) -> 34.1 | K36: =SUM(H36:J36) -> 166.8 | L36: =1-E36/H36 -> 0.86200194 | M36: 1 | N36: 1
A37: Småhus | B37: TEK97 | C37: Oppgradering av vinduer standard | D37: 1 | E37: 14.2 | F37: 0 | G37: 0 | H37: ='Energibehov før tiltak'!$D$4 -> 102.9 | I37: ='Energibehov før tiltak'!$D$6 -> 29.8 | J37: =SUM('Energibehov før tiltak'!$D$5,'Energibehov før tiltak'!$D$7:$D$12) -> 34.1 | K37: =SUM(H37:J37) -> 166.8 | L37: =1-E37/H37 -> 0.86200194 | M37: 1 | N37: 1
A38: Småhus | B38: TEK97 | C38: Temperaturstyring | D38: 0 | E38: 0 | F38: 0 | G38: 0 | H38: ='Energibehov før tiltak'!$D$4 -> 102.9 | I38: ='Energibehov før tiltak'!$D$6 -> 29.8 | J38: =SUM('Energibehov før tiltak'!$D$5,'Energibehov før tiltak'!$D$7:$D$12) -> 34.1 | K38: =SUM(H38:J38) -> 166.8 | L38: =1-E38/H38 -> 1 | M38: 1 | N38: 1
A39: Småhus | B39: TEK97 | C39: Luft-luft varmepumpe | D39: 1 | E39: =(1-L39)*H39 -> 33.676364 | F39: =(1-M39)*I39 -> 0 | G39: =(1-N39)*J39 -> 0 | H39: ='Energibehov før tiltak'!$D$4 -> 102.9 | I39: ='Energibehov før tiltak'!$D$6 -> 29.8 | J39: =SUM('Energibehov før tiltak'!$D$5,'Energibehov før tiltak'!$D$7:$D$12) -> 34.1 | K39: =SUM(H39:J39) -> 166.8 | L39: ='Regler varmepumper'!E24 -> 0.67272727 | M39: ='Regler varmepumper'!E25 -> 1 | N39: ='Regler varmepumper'!E26 -> 1
A40: Småhus | B40: TEK97 | C40: Luft-væske varmepumpe | D40: 1 | E40: =(1-L40)*H40 -> 49.392 | F40: =(1-M40)*I40 -> 8.94 | G40: =(1-N40)*J40 -> 0 | H40: ='Energibehov før tiltak'!$D$4 -> 102.9 | I40: ='Energibehov før tiltak'!$D$6 -> 29.8 | J40: =SUM('Energibehov før tiltak'!$D$5,'Energibehov før tiltak'!$D$7:$D$12) -> 34.1 | K40: =SUM(H40:J40) -> 166.8 | L40: ='Regler varmepumper'!E27 -> 0.52 | M40: ='Regler varmepumper'!E28 -> 0.7 | N40: ='Regler varmepumper'!E29 -> 1
...

Sheet Energibehov før tiltak
B1: Småhus | C1: Småhus | D1: Småhus | E1: Småhus | F1: Småhus | G1: Småhus | H1: Boligblokk | I1: Boligblokk | J1: Boligblokk | K1: Boligblokk | L1: Boligblokk | M1: Boligblokk
A2: Multiconsult | B2: TEK69 | C2: TEK87 | D2: TEK97 | E2: TEK07 | F2: TEK10 | G2: TEK17 | H2: TEK69 | I2: TEK87 | J2: TEK97 | K2: TEK07 | L2: TEk10 | M2: TEK17
A3: Forbruk før enøk | B3: [kWh/m²] | C3: [kWh/m²] | D3: [kWh/m²] | E3: [kWh/m²] | F3: [kWh/m²] | G3: [kWh/m²] | H3: [kWh/m²] | I3: [kWh/m²] | J3: [kWh/m²] | K3: [kWh/m²] | L3: [kWh/m²] | M3: [kWh/m²]
A4: Romoppvarming | B4: 180.4 | C4: 141.4 | D4: 102.9 | E4: 53.5 | F4: 45.3 | G4: 45.3 | H4: 162.4 | I4: 111.9 | J4: 89.1 | K4: 33.2 | L4: 24.7 | M4: 24.7
A5: Ventilasjonsvarme (varmebatterier) | B5: 0 | C5: 0 | D5: 0 | E5: 9.2 | F5: 9.2 | G5: 9.2 | H5: 0 | I5: 0 | J5: 0 | K5: 11.2 | L5: 11.2 | M5: 11.2
A6: Oppvarming av tappevann | B6: 29.8 | C6: 29.8 | D6: 29.8 | E6: 29.8 | F6: 29.8 | G6: 29.8 | H6: 29.8 | I6: 29.8 | J6: 29.8 | K6: 29.8 | L6: 29.8 | M6: 29.8
A7: Vifter (ventilasjon) | B7: 0 | C7: 0 | D7: 4.4 | E7: 7.3 | F7: 7.3 | G7: 7.3 | H7: 0 | I7: 0 | J7: 5.5 | K7: 9.1 | L7: 9.1 | M7: 9.1
A8: Pumper | B8: 1.2 | C8: 1 | D8: 0.8 | E8: 0.5 | F8: 0.5 | G8: 0.5 | H8: 1.1 | I8: 0.8 | J8: 0.6 | K8: 0.3 | L8: 0.3 | M8: 0.3
A9: Belysning | B9: 11.4 | C9: 11.4 | D9: 11.4 | E9: 11.4 | F9: 11.4 | G9: 11.4 | H9: 11.4 | I9: 11.4 | J9: 11.4 | K9: 11.4 | L9: 11.4 | M9: 11.4
A10: Teknisk utstyr | B10: 17.5 | C10: 17.5 | D10: 17.5 | E10: 17.5 | F10: 17.5 | G10: 17.5 | H10: 17.5 | I10: 17.5 | J10: 17.5 | K10: 17.5 | L10: 17.5 | M10: 17.5
A11: Romkjøling | B11: 0 | C11: 0 | D11: 0 | E11: 0 | F11: 0 | G11: 0 | H11: 0 | I11: 0 | J11: 0 | K11: 0 | L11: 0 | M11: 0
A12: Ventilasjonskjøling (kjølebatterier) | B12: 0 | C12: 0 | D12: 0 | E12: 0 | F12: 0 | G12: 0 | H12: 0 | I12: 0 | J12: 0 | K12: 0 | L12: 0 | M12: 0
A13: Total | B13: 240.2 | C13: 201 | D13: 166.7 | E13: 129.2 | F13: 121 | G13: 121 | H13: 222.1 | I13: 171.4 | J13: 153.8 | K13: 112.5 | L13: 104 | M13: 104

Sheet Regler varmepumper
C2: TEK 69 | D2: TEK 87 | E2: TEK 97 | F2: TEK 07 | G2: TEK 10 | H2: TEK 17 | I2: TEK 69 | J2: TEK 87 | K2: TEK 97 | L2: TEK 07 | M2: TEK 10 | N2: TEK 17
C3: Småhus | D3: Småhus | E3: Småhus | F3: Småhus | G3: Småhus | H3: Småhus | I3: Boligblokk | J3: Boligblokk | K3: Boligblokk | L3: Boligblokk | M3: Boligblokk | N3: Boligblokk
B4: Forbruk før enøk | C4: kWh/år | D4: kWh/år | E4: kWh/år | F4: kWh/år | G4: kWh/år | H4: kWh/år | I4: kWh/år | J4: kWh/år | K4: kWh/år | L4: kWh/år | M4: kWh/år | N4: kWh/år
B5: Romoppvarming | C5: 28859 | D5: 22619 | E5: 16463 | F5: 8556 | G5: 7253 | H5: 7253 | I5: 146125 | J5: 100731 | K5: 80202 | L5: 29896 | M5: 23452 | N5: 23452
B6: Ventilasjonsvarme (varmebatterier) | C6: 0 | D6: 0 | E6: 0 | F6: 1475 | G6: 1482 | H6: 1482 | I6: 0 | J6: 0 | K6: 0 | L6: 10060 | M6: 10073 | N6: 10073
B7: Oppvarming av tappevann | C7: 4765 | D7: 4765 | E7: 4765 | F7: 4765 | G7: 4765 | H7: 4765 | I7: 26792 | J7: 26792 | K7: 26792 | L7: 26792 | M7: 26792 | N7: 26792
B8: Vifter (ventilasjon) | C8: 0 | D8: 0 | E8: 701 | F8: 1168 | G8: 1168 | H8: 1168 | I8: 0 | J8: 0 | K8: 4925 | L8: 8216 | M8: 8216 | N8: 8216
B9: Pumper | C9: 190 | D9: 158 | E9: 123 | F9: 82 | G9: 72 | H9: 72 | I9: 951 | J9: 742 | K9: 511 | L9: 246 | M9: 208 | N9: 208
B10: Belysning | C10: 1822 | D10: 1822 | E10: 1822 | F10: 1822 | G10: 1822 | H10: 1822 | I10: 10253 | J10: 10253 | K10: 10253 | L10: 10253 | M10: 10253 | N10: 10253
B11: Teknisk utstyr | C11: 2803 | D11: 2803 | E11: 2803 | F11: 2803 | G11: 2803 | H11: 2803 | I11: 15768 | J11: 15768 | K11: 15768 | L11: 15768 | M11: 15768 | N11: 15768
B12: Romkjøling | C12: 0 | D12: 0 | E12: 0 | F12: 0 | G12: 0 | H12: 0 | I12: 0 | J12: 0 | K12: 0 | L12: 0 | M12: 0 | N12: 0
B13: Ventilasjonskjøling (kjølebatterier) | C13: 0 | D13: 0 | E13: 0 | F13: 0 | G13: 0 | H13: 0 | I13: 0 | J13: 0 | K13: 0 | L13: 0 | M13: 0 | N13: 0
B14: Total | C14: =SUM(C5:C13) -> 38439 | D14: =SUM(D5:D13) -> 32167 | E14: =SUM(E5:E13) -> 26677 | F14: =SUM(F5:F13) -> 20671 | G14: =SUM(G6:G13) -> 12112 | H14: =SUM(H6:H13) -> 12112 | I14: =SUM(I5:I13) -> 199889 | J14: =SUM(J5:J13) -> 154286 | K14: =SUM(K5:K13) -> 138451 | L14: =SUM(L5:L13) -> 101231 | M14: =SUM(M6:M13) -> 71310 | N14: =SUM(N6:N13) -> 71310
B15: Romoppvarming | C15: =C5+C6 -> 28859 | D15: =D5+D6 -> 22619 | E15: =E5+E6 -> 16463 | F15: =F5+F6 -> 10031 | G15: =G5+G6 -> 8735 | H15: =H5+H6 -> 8735 | I15: =I5+I6 -> 146125 | J15: =J5+J6 -> 100731 | ... N15: =N5+N6 -> 33525
B16: Tappevann | C16: =(C7) -> 4765 | D16: =(D7) -> 4765 | E16: =(E7) -> 4765 | F16: =(F7) -> 4765 | G16: =(G7) -> 4765 | H16: =(H7) -> 4765 | I16: =(I7) -> 26792 | J16: =(J7) -> 26792 | ... N16: =(N7) -> 26792
B17: Elspesifikt | C17: =SUM(C9:C13) -> 4815 | D17: =SUM(D9:D13) -> 4783 | E17: =SUM(E9:E13) -> 4748 | F17: =SUM(F9:F13) -> 4707 | G17: =SUM(G9:G13) -> 4697 | H17: =SUM(H9:H13) -> 4697 | I17: =SUM(I9:I13) -> 26972 | J17: =SUM(J9:J13) -> 26763 | ... N17: =SUM(N9:N13) -> 26229
B18: Total | C18: =SUM(C15:C17) -> 38439 | D18: =SUM(D15:D17) -> 32167 | E18: =SUM(E15:E17) -> 25976 | F18: =SUM(F15:F17) -> 19503 | G18: =SUM(G15:G17) -> 18197 | H18: =SUM(H15:H17) -> 18197 | I18: =SUM(I15:I17) -> 199889 | J18: =SUM(J15:J17) -> 154286 | ... N18: =SUM(N15:N17) -> 86546
B19: Romoppvarming | C19: =C15/C$18 -> 0.75077395 | D19: =D15/D$18 -> 0.70317406 | E19: =E15/E$18 -> 0.63377733 | F19: =F15/F$18 -> 0.51433113 | G19: =G15/G$18 -> 0.48002418 | H19: =H15/H$18 -> 0.48002418 | I19: =I15/I$18 -> 0.73103072 | J19: =J15/J$18 -> 0.6528849 | ... N19: =N15/N$18 -> 0.38736626
B20: Tappevann | C20: =C16/C$18 -> 0.12396264 | D20: =D16/D$18 -> 0.14813318 | E20: =E16/E$18 -> 0.18343856 | F20: =F16/F$18 -> 0.24432139 | G20: =G16/G$18 -> 0.26185635 | H20: =H16/H$18 -> 0.26185635 | I20: =I16/I$18 -> 0.13403439 | J20: =J16/J$18 -> 0.17365153 | ... N20: =N16/N$18 -> 0.30956948
B21: Elspesifikt | C21: =C17/C$18 -> 0.1252634 | D21: =D17/D$18 -> 0.14869276 | E21: =E17/E$18 -> 0.18278411 | F21: =F17/F$18 -> 0.24134749 | G21: =G17/G$18 -> 0.25811947 | H21: =H17/H$18 -> 0.25811947 | I21: =I17/I$18 -> 0.13493489 | J21: =J17/J$18 -> 0.17346357 | ... N21: =N17/N$18 -> 0.30306427
B22: Sjekk | C22: =SUM(C19:C21) -> 1 | D22: =SUM(D19:D21) -> 1 | E22: =SUM(E19:E21) -> 1 | F22: =SUM(F19:F21) -> 1 | G22: =SUM(G19:G21) -> 1 | H22: =SUM(H19:H21) -> 1 | I22: =SUM(I19:I21) -> 1 | J22: =SUM(J19:J21) -> 1 | ... N22: =SUM(N19:N21) -> 1
A24: Luft - luft | B24: Romoppvarming | C24: =1-(($C$38)*(1-1/$C$37)) -> 0.67272727 | D24: =1-(($C$38)*(1-1/$C$37)) -> 0.67272727 | E24: =1-(($C$38)*(1-1/$C$37)) -> 0.67272727 | F24: =1-(($C$38)*(1-1/$C$37)) -> 0.67272727 | G24: =1-(($C$38)*(1-1/$C$37)) -> 0.67272727 | H24: =1-(($C$38)*(1-1/$C$37)) -> 0.67272727 | I24: =1-(($C$38)*(1-1/$C$37)) -> 0.67272727 | J24: =1-(($C$38)*(1-1/$C$37)) -> 0.67272727 | ... N24: =1-(($C$38)*(1-1/$C$37)) -> 0.67272727
B25: Tappevann | C25: =1-(($D$38)*(1-1/$D$37)) -> 1 | D25: =1-(($D$38)*(1-1/$D$37)) -> 1 | E25: =1-(($D$38)*(1-1/$D$37)) -> 1 | F25: =1-(($D$38)*(1-1/$D$37)) -> 1 | G25: =1-(($D$38)*(1-1/$D$37)) -> 1 | H25: =1-(($D$38)*(1-1/$D$37)) -> 1 | I25: =1-(($D$38)*(1-1/$D$37)) -> 1 | J25: =1-(($D$38)*(1-1/$D$37)) -> 1 | ... N25: =1-(($D$38)*(1-1/$D$37)) -> 1
B26: Elspesifikt | C26: =1-(($E$38)*(1-1/$E$37)) -> 1 | D26: =1-(($E$38)*(1-1/$E$37)) -> 1 | E26: =1-(($E$38)*(1-1/$E$37)) -> 1 | F26: =1-(($E$38)*(1-1/$E$37)) -> 1 | G26: =1-(($E$38)*(1-1/$E$37)) -> 1 | H26: =1-(($E$38)*(1-1/$E$37)) -> 1 | I26: =1-(($E$38)*(1-1/$E$37)) -> 1 | J26: =1-(($E$38)*(1-1/$E$37)) -> 1 | ... N26: =1-(($E$38)*(1-1/$E$37)) -> 1
A27: Væske - luft | B27: Romoppvarming | C27: =1-(($C$40)*(1-1/$C$39)) -> 0.52 | D27: =1-(($C$40)*(1-1/$C$39)) -> 0.52 | E27: =1-(($C$40)*(1-1/$C$39)) -> 0.52 | F27: =1-(($C$40)*(1-1/$C$39)) -> 0.52 | G27: =1-(($C$40)*(1-1/$C$39)) -> 0.52 | H27: =1-(($C$40)*(1-1/$C$39)) -> 0.52 | I27: =1-(($C$40)*(1-1/$C$39)) -> 0.52 | J27: =1-(($C$40)*(1-1/$C$39)) -> 0.52 | ... N27: =1-(($C$40)*(1-1/$C$39)) -> 0.52
B28: Tappevann | C28: =1-(($D$40)*(1-1/$D$39)) -> 0.7 | D28: =1-(($D$40)*(1-1/$D$39)) -> 0.7 | E28: =1-(($D$40)*(1-1/$D$39)) -> 0.7 | F28: =1-(($D$40)*(1-1/$D$39)) -> 0.7 | G28: =1-(($D$40)*(1-1/$D$39)) -> 0.7 | H28: =1-(($D$40)*(1-1/$D$39)) -> 0.7 | I28: =1-(($D$40)*(1-1/$D$39)) -> 0.7 | J28: =1-(($D$40)*(1-1/$D$39)) -> 0.7 | ... N28: =1-(($D$40)*(1-1/$D$39)) -> 0.7
B29: Elspesifikt | C29: =1-(($E$40)*(1-1/$E$39)) -> 1 | D29: =1-(($E$40)*(1-1/$E$39)) -> 1 | E29: =1-(($E$40)*(1-1/$E$39)) -> 1 | F29: =1-(($E$40)*(1-1/$E$39)) -> 1 | G29: =1-(($E$40)*(1-1/$E$39)) -> 1 | H29: =1-(($E$40)*(1-1/$E$39)) -> 1 | I29: =1-(($E$40)*(1-1/$E$39)) -> 1 | J29: =1-(($E$40)*(1-1/$E$39)) -> 1 | ... N29: =1-(($E$40)*(1-1/$E$39)) -> 1
A30: Væske - væske | B30: Romoppvarming | C30: =1-(($C$42)*(1-1/$C$41)) -> 0.32142857 | D30: =1-(($C$42)*(1-1/$C$41)) -> 0.32142857 | E30: =1-(($C$42)*(1-1/$C$41)) -> 0.32142857 | F30: =1-(($C$42)*(1-1/$C$41)) -> 0.32142857 | G30: =1-(($C$42)*(1-1/$C$41)) -> 0.32142857 | H30: =1-(($C$42)*(1-1/$C$41)) -> 0.32142857 | I30: =1-(($C$42)*(1-1/$C$41)) -> 0.32142857 | J30: =1-(($C$42)*(1-1/$C$41)) -> 0.32142857 | ... N30: =1-(($C$42)*(1-1/$C$41)) -> 0.32142857
B31: Tappevann | C31: =1-(($D$42)*(1-1/$D$41)) -> 0.64 | D31: =1-(($D$42)*(1-1/$D$41)) -> 0.64 | E31: =1-(($D$42)*(1-1/$D$41)) -> 0.64 | F31: =1-(($D$42)*(1-1/$D$41)) -> 0.64 | G31: =1-(($D$42)*(1-1/$D$41)) -> 0.64 | H31: =1-(($D$42)*(1-1/$D$41)) -> 0.64 | I31: =1-(($D$42)*(1-1/$D$41)) -> 0.64 | J31: =1-(($D$42)*(1-1/$D$41)) -> 0.64 | ... N31: =1-(($D$42)*(1-1/$D$41)) -> 0.64
B32: Elspesifikt | C32: =1-(($E$42)*(1-1/$E$41)) -> 1 | D32: =1-(($E$42)*(1-1/$E$41)) -> 1 | E32: =1-(($E$42)*(1-1/$E$41)) -> 1 | F32: =1-(($E$42)*(1-1/$E$41)) -> 1 | G32: =1-(($E$42)*(1-1/$E$41)) -> 1 | H32: =1-(($E$42)*(1-1/$E$41)) -> 1 | I32: =1-(($E$42)*(1-1/$E$41)) -> 1 | J32: =1-(($E$42)*(1-1/$E$41)) -> 1 | ... N32: =1-(($E$42)*(1-1/$E$41)) -> 1
C36: Romoppvarming | D36: Tappevann | E36: Elspesifikt
B37: Virkningsgrad luft-luft | C37: 2.2 | D37: 1 | E37: 1
B38: Dekningsgrad luft-luft | C38: 0.6 | D38: 0 | E38: 0
B39: Virkningsgrad luft-væske | C39: 2.5 | D39: 2 | E39: 1
B40: Dekningsgrad luft-væske | C40: 0.8 | D40: 0.6 | E40: 0
B41: Virkningsgrad væske-væske | C41: 3.5 | D41: 2.5 | E41: 1
B42: Dekningsgrad væske-væske | C42: 0.95 | D42: 0.6 | E42: 0
